<?xml version="1.0"?>
<robot xmlns:xacro="http://www.ros.org/wiki/xacro">


    <material name="white">
    <color rgba="1 1 1 1"/>
    </material>

    <material name="orange">
    <color rgba="1 0.3 0.1 1"/>
    </material>

    <material name="blue">
    <color rgba="0.2 0.2 1 1"/>
    </material>

    <material name="black">
    <color rgba="0 0 0 1"/>
    </material>







    <!-- The Solidworks generated urdf starts from here -->

    <link name="dummy">
   </link>

    <joint name="dummy_joint" type="fixed">
     <parent link="dummy"/>
     <child link="base_link"/>
   </joint>


    <link
    name="base_link">
    <inertial>
      <origin
        xyz="-0.13058 -0.075146 -0.064102"
        rpy="0 0 0" />
      <mass
        value="7.2522" />
      <inertia
        ixx="0.049215"
        ixy="1.0185E-06"
        ixz="-5.3255E-05"
        iyy="0.077749"
        iyz="-0.003306"
        izz="0.054205" />
    </inertial>
    <visual>
      <origin
        xyz="0 0 0"
        rpy="0 0 0" />
      <geometry>
        <mesh
          filename="file://$(find auriga)/description/meshes/base_link.STL" />
      </geometry>
      <material
        name="">
        <color
          rgba="0.2 0.2 0.2 1" />
      </material>
    </visual>
    <collision>
      <origin
        xyz="0 0 0"
        rpy="0 0 0" />
      <geometry>
        <mesh
          filename="file://$(find auriga)/description/meshes/base_link.STL" />
      </geometry>
    </collision>
  </link>



  <link
    name="rocker_1_link">
    <inertial>
      <origin
        xyz="-0.0031943 0.077406 0.051422"
        rpy="0 0 0" />
      <mass
        value="1.4" />
      <inertia
        ixx="0.0029865"
        ixy="1.1235E-05"
        ixz="3.1664E-05"
        iyy="0.0025991"
        iyz="-0.00067818"
        izz="0.00041191" />
    </inertial>
    <visual>
      <origin
        xyz="0 0 0"
        rpy="0 0 0" />
      <geometry>
        <mesh
          filename="file://$(find auriga)/description/meshes/rocker_1_link.STL" />
      </geometry>
      <material
        name="">
        <color
          rgba="0.42745 0.44706 0.42745 1" />
      </material>
    </visual>
    <collision>
      <origin
        xyz="0 0 0"
        rpy="0 0 0" />
      <geometry>
        <mesh
          filename="file://$(find auriga)/description/meshes/rocker_1_link.STL" />
      </geometry>
    </collision>
  </link>
  <joint
    name="rocker_1_joint"
    type="fixed">
    <origin
      xyz="0.03499 -0.092655 -0.033"
      rpy="3.1416 0 3.1416" />
    <parent
      link="base_link" />
    <child
      link="rocker_1_link" />
    <axis
      xyz="0 0 0" />
  </joint>
  <link
    name="bogie_1_link">
    <inertial>
      <origin
        xyz="0.0023959 -0.061899 -8.3267E-17"
        rpy="0 0 0" />
      <mass
        value="1" />
      <inertia
        ixx="0.00075509"
        ixy="4.3843E-06"
        ixz="7.2993E-20"
        iyy="0.00066526"
        iyz="-3.1639E-20"
        izz="0.0001028" />
    </inertial>
    <visual>
      <origin
        xyz="0 0 0"
        rpy="0 0 0" />
      <geometry>
        <mesh
          filename="file://$(find auriga)/description/meshes/bogie_1_link.STL" />
      </geometry>
      <material
        name="">
        <color
          rgba="0.42745 0.44706 0.42745 1" />
      </material>
    </visual>
    <collision>
      <origin
        xyz="0 0 0"
        rpy="0 0 0" />
      <geometry>
        <mesh
          filename="file://$(find auriga)/description/meshes/bogie_1_link.STL" />
      </geometry>
    </collision>
  </link>
  <joint
    name="bogie_1_joint"
    type="revolute">
    <origin
      xyz="-0.02051 0.053967 -0.1"
      rpy="0 0 3.1416" />
    <parent
      link="rocker_1_link" />
    <child
      link="bogie_1_link" />
    <axis
      xyz="-1 0 0" />
    <limit
      lower="-0.785"
      upper="0.785"
      effort="10"
      velocity="5" />
  </joint>
  <link
    name="wheel_5_link">
    <inertial>
      <origin
        xyz="0.0073954 -0.00033419 5.8975E-05"
        rpy="0 0 0" />
      <mass
        value="1.3" />
      <inertia
        ixx="0.0022259"
        ixy="4.5416E-06"
        ixz="-8.1867E-07"
        iyy="0.0014255"
        iyz="8.9816E-07"
        izz="0.0014302" />
    </inertial>
    <visual>
      <origin
        xyz="0 0 0"
        rpy="0 0 0" />
      <geometry>
        <mesh
          filename="file://$(find auriga)/description/meshes/wheel_5_link.STL" />
      </geometry>
      <material
        name="">
        <color
          rgba="0.75294 0.75294 0.75294 1" />
      </material>
    </visual>
    <collision>
      <origin
        xyz="0 0 0"
        rpy="0 0 0" />
      <geometry>
        <mesh
          filename="file://$(find auriga)/description/meshes/wheel_5_link.STL" />
      </geometry>
    </collision>
  </link>
  <joint
    name="wheel_5_joint"
    type="continuous">
    <origin
      xyz="0.0906500000000005 -0.0786880243269096 0.0900000000000002"
      rpy="0 0 3.14159265358979" />
    <parent
      link="bogie_1_link" />
    <child
      link="wheel_5_link" />
    <axis
      xyz="-1 0 0" />
  </joint>
  <link
    name="wheel_6_link">
    <inertial>
      <origin
        xyz="0.0073954 -0.0003392 -0.38999"
        rpy="0 0 0" />
      <mass
        value="1.3" />
      <inertia
        ixx="0.0022259"
        ixy="4.6122E-06"
        ixz="-1.5572E-07"
        iyy="0.0014254"
        iyz="1.9352E-07"
        izz="0.0014304" />
    </inertial>
    <visual>
      <origin
        xyz="0 0 0"
        rpy="0 0 0" />
      <geometry>
        <mesh
          filename="file://$(find auriga)/description/meshes/wheel_6_link.STL" />
      </geometry>
      <material
        name="">
        <color
          rgba="0.75294 0.75294 0.75294 1" />
      </material>
    </visual>
    <collision>
      <origin
        xyz="0 0 0"
        rpy="0 0 0" />
      <geometry>
        <mesh
          filename="file://$(find auriga)/description/meshes/wheel_6_link.STL" />
      </geometry>
    </collision>
  </link>
  <joint
    name="wheel_6_joint"
    type="continuous">
    <origin
      xyz="0.09065 -0.0786880243269102 0.3"
      rpy="0 0 3.14159265358979" />
    <parent
      link="bogie_1_link" />
    <child
      link="wheel_6_link" />
    <axis
      xyz="-1 0 0" />
  </joint>
  <link
    name="wheel_4_link">
    <inertial>
      <origin
        xyz="0.0073954 0.00024372 0.39024"
        rpy="0 0 0" />
      <mass
        value="1.3" />
      <inertia
        ixx="0.0022259"
        ixy="-3.3261E-06"
        ixz="-3.199E-06"
        iyy="0.0014277"
        iyz="-2.5036E-06"
        izz="0.001428" />
    </inertial>
    <visual>
      <origin
        xyz="0 0 0"
        rpy="0 0 0" />
      <geometry>
        <mesh
          filename="file://$(find auriga)/description/meshes/wheel_4_link.STL" />
      </geometry>
      <material
        name="">
        <color
          rgba="0.75294 0.75294 0.75294 1" />
      </material>
    </visual>
    <collision>
      <origin
        xyz="0 0 0"
        rpy="0 0 0" />
      <geometry>
        <mesh
          filename="file://$(find auriga)/description/meshes/wheel_4_link.STL" />
      </geometry>
    </collision>
  </link>
  <joint
    name="wheel_4_joint"
    type="continuous">
    <origin
      xyz="-0.111159632502295 0.132654956914557 -0.19"
      rpy="0 0 0" />
    <parent
      link="rocker_1_link" />
    <child
      link="wheel_4_link" />
    <axis
      xyz="-1 0 0" />
  </joint>
  <link
    name="rocker_2_link">
    <inertial>
      <origin
        xyz="-0.30934 -0.015249 -0.084422"
        rpy="0 0 0" />
      <mass
        value="1.4" />
      <inertia
        ixx="0.0029865"
        ixy="1.1235E-05"
        ixz="-3.1664E-05"
        iyy="0.0025991"
        iyz="0.00067818"
        izz="0.00041191" />
    </inertial>
    <visual>
      <origin
        xyz="0 0 0"
        rpy="0 0 0" />
      <geometry>
        <mesh
          filename="file://$(find auriga)/description/meshes/rocker_2_link.STL" />
      </geometry>
      <material
        name="">
        <color
          rgba="0.42745 0.44706 0.42745 1" />
      </material>
    </visual>
    <collision>
      <origin
        xyz="0 0 0"
        rpy="0 0 0" />
      <geometry>
        <mesh
          filename="file://$(find auriga)/description/meshes/rocker_2_link.STL" />
      </geometry>
    </collision>
  </link>
  <joint
    name="rocker_2_joint"
    type="fixed">
    <origin
      xyz="0 0 0"
      rpy="0 0 0" />
    <parent
      link="base_link" />
    <child
      link="rocker_2_link" />
    <axis
      xyz="0 0 0" />
  </joint>
  <link
    name="bogie_2_link">
    <inertial>
      <origin
        xyz="0.0023959 0.061897 -0.00066505"
        rpy="0 0 0" />
      <mass
        value="1" />
      <inertia
        ixx="0.00075509"
        ixy="-4.384E-06"
        ixz="4.7104E-08"
        iyy="0.00066519"
        iyz="-6.0427E-06"
        izz="0.00010286" />
    </inertial>
    <visual>
      <origin
        xyz="0 0 0"
        rpy="0 0 0" />
      <geometry>
        <mesh
          filename="file://$(find auriga)/description/meshes/bogie_2_link.STL" />
      </geometry>
      <material
        name="">
        <color
          rgba="0.42745 0.44706 0.42745 1" />
      </material>
    </visual>
    <collision>
      <origin
        xyz="0 0 0"
        rpy="0 0 0" />
      <geometry>
        <mesh
          filename="file://$(find auriga)/description/meshes/bogie_2_link.STL" />
      </geometry>
    </collision>
  </link>
  <joint
    name="bogie_2_joint"
    type="revolute">
    <origin
      xyz="-0.32665 -0.038688 0.066853"
      rpy="3.1416 0 3.1416" />
    <parent
      link="rocker_2_link" />
    <child
      link="bogie_2_link" />
    <axis
      xyz="-1 0 0" />
    <limit
      lower="-0.785"
      upper="0.785"
      effort="10"
      velocity="5" />
  </joint>
  <link
    name="wheel_2_link">
    <inertial>
      <origin
        xyz="6.7458E-05 -0.00033338 -0.0073954"
        rpy="0 0 0" />
      <mass
        value="1.3" />
      <inertia
        ixx="0.0014302"
        ixy="1.016E-06"
        ixz="9.3391E-07"
        iyy="0.0014256"
        iyz="-4.5193E-06"
        izz="0.0022259" />
    </inertial>
    <visual>
      <origin
        xyz="0 0 0"
        rpy="0 0 0" />
      <geometry>
        <mesh
          filename="file://$(find auriga)/description/meshes/wheel_2_link.STL" />
      </geometry>
      <material
        name="">
        <color
          rgba="0.75294 0.75294 0.75294 1" />
      </material>
    </visual>
    <collision>
      <origin
        xyz="0 0 0"
        rpy="0 0 0" />
      <geometry>
        <mesh
          filename="file://$(find auriga)/description/meshes/wheel_2_link.STL" />
      </geometry>
    </collision>
  </link>
  <joint
    name="wheel_2_joint"
    type="continuous">
    <origin
      xyz="0.0906500000000001 0.0796504434421384 0.0891493804349932"
      rpy="0 -1.5707963267949 0" />
    <parent
      link="bogie_2_link" />
    <child
      link="wheel_2_link" />
    <axis
      xyz="0 0 1" />
  </joint>
  <link
    name="wheel_1_link">
    <inertial>
      <origin
        xyz="-0.0073954 0.00028789 -0.00018094"
        rpy="0 0 0" />
      <mass
        value="1.3" />
      <inertia
        ixx="0.0022259"
        ixy="3.9131E-06"
        ixz="-2.4463E-06"
        iyy="0.0014267"
        iyz="2.2425E-06"
        izz="0.001429" />
    </inertial>
    <visual>
      <origin
        xyz="0 0 0"
        rpy="0 0 0" />
      <geometry>
        <mesh
          filename="file://$(find auriga)/description/meshes/wheel_1_link.STL" />
      </geometry>
      <material
        name="">
        <color
          rgba="0.75294 0.75294 0.75294 1" />
      </material>
    </visual>
    <collision>
      <origin
        xyz="0 0 0"
        rpy="0 0 0" />
      <geometry>
        <mesh
          filename="file://$(find auriga)/description/meshes/wheel_1_link.STL" />
      </geometry>
    </collision>
  </link>
  <joint
    name="wheel_1_joint"
    type="continuous">
    <origin
      xyz="0.09065 0.0777165216962496 -0.0908402302281802"
      rpy="0 0 0" />
    <parent
      link="bogie_2_link" />
    <child
      link="wheel_1_link" />
    <axis
      xyz="1 0 0" />
  </joint>
  <link
    name="wheel_3_link">
    <inertial>
      <origin
        xyz="-0.0073954 0.00030624 0.00014786"
        rpy="0 0 0" />
      <mass
        value="1.3" />
      <inertia
        ixx="0.0022259"
        ixy="4.1463E-06"
        ixz="2.0259E-06"
        iyy="0.0014263"
        iyz="-1.9924E-06"
        izz="0.0014294" />
    </inertial>
    <visual>
      <origin
        xyz="0 0 0"
        rpy="0 0 0" />
      <geometry>
        <mesh
          filename="file://$(find auriga)/description/meshes/wheel_3_link.STL" />
      </geometry>
      <material
        name="">
        <color
          rgba="0.75294 0.75294 0.75294 1" />
      </material>
    </visual>
    <collision>
      <origin
        xyz="0 0 0"
        rpy="0 0 0" />
      <geometry>
        <mesh
          filename="file://$(find auriga)/description/meshes/wheel_3_link.STL" />
      </geometry>
    </collision>
  </link>
  <joint
    name="wheel_3_joint"
    type="continuous">
    <origin
      xyz="-0.417304617315038 0.0399992013357422 -0.2329999973597"
      rpy="3.14159265358979 0 3.14159265358979" />
    <parent
      link="rocker_2_link" />
    <child
      link="wheel_3_link" />
    <axis
      xyz="1 0 0" />
  </joint>
  <link
    name="lidar_link">
    <inertial>
      <origin
        xyz="0.022525 0.025224 0.0068988"
        rpy="0 0 0" />
      <mass
        value="0.1" />
      <inertia
        ixx="4.4351E-05"
        ixy="2.9037E-08"
        ixz="-1.5175E-07"
        iyy="6.9475E-05"
        iyz="3.35E-07"
        izz="2.791E-05" />
    </inertial>
    <visual>
      <origin
        xyz="0 0 0"
        rpy="0 0 0" />
      <geometry>
        <mesh
          filename="file://$(find auriga)/description/meshes/lidar_link.STL" />
      </geometry>
      <material
        name="">
        <color
          rgba="0.75294 0.75294 0.75294 1" />
      </material>
    </visual>
    <collision>
      <origin
        xyz="0 0 0"
        rpy="0 0 0" />
      <geometry>
        <mesh
          filename="file://$(find auriga)/description/meshes/lidar_link.STL" />
      </geometry>
    </collision>
  </link>
  <joint
    name="lidar_joint"
    type="fixed">
    <origin
      xyz="-0.11141 -0.23235 0.072107"
      rpy="3.1416 0 3.1416" />
    <parent
      link="base_link" />
    <child
      link="lidar_link" />
    <axis
      xyz="0 0 0" />
  </joint>
  <link
    name="camera_link">
    <inertial>
      <origin
        xyz="0 0 0"
        rpy="0 0 0" />
      <mass
        value="0.1" />
      <inertia
        ixx="0"
        ixy="0"
        ixz="0"
        iyy="0"
        iyz="0"
        izz="0" />
    </inertial>
    <visual>
      <origin
        xyz="0 0 0"
        rpy="0 0 0" />
      <geometry>
        <mesh
          filename="file://$(find auriga)/description/meshes/camera_link.STL" />
      </geometry>
      <material
        name="">
        <color
          rgba="1 1 1 1" />
      </material>
    </visual>
    <collision>
      <origin
        xyz="0 0 0"
        rpy="0 0 0" />
      <geometry>
        <mesh
          filename="file://$(find auriga)/description/meshes/camera_link.STL" />
      </geometry>
    </collision>
  </link>
  <joint
    name="camera_joint"
    type="fixed">
    <origin
      xyz="-0.113225697052003 -0.0537931754289137 0.146634965177554"
      rpy="3.14159265358979 0 3.14159265358979" />
    <parent
      link="base_link" />
    <child
      link="camera_link" />
    <axis
      xyz="0 0 0" />
  </joint>


</robot>