<?xml version="1.0"?>
<robot xmlns:xacro="http://www.ros.org/wiki/xacro">


    <material name="white">
    <color rgba="1 1 1 1"/>
    </material>

    <material name="orange">
    <color rgba="1 0.3 0.1 1"/>
    </material>

    <material name="blue">
    <color rgba="0.2 0.2 1 1"/>
    </material>

    <material name="black">
    <color rgba="0 0 0 1"/>
    </material>







    <!-- The Solidworks generated urdf starts from here -->

    <link name="dummy">
   </link>

    <joint name="dummy_joint" type="fixed">
     <parent link="dummy"/>
     <child link="base_link"/>
   </joint>

 <link
    name="base_link">
    <inertial>
      <origin
        xyz="-0.13058 -0.075146 -0.064102"
        rpy="0 0 0" />
      <mass
        value="7.2522" />
      <inertia
        ixx="0.049215"
        ixy="1.0185E-06"
        ixz="-5.3255E-05"
        iyy="0.077749"
        iyz="-0.003306"
        izz="0.054205" />
    </inertial>
    <visual>
      <origin
        xyz="0 0 0"
        rpy="0 0 0" />
      <geometry>
        <mesh
          filename="file://$(find auriga)/description/meshes/base_link.STL" />
      </geometry>
      <material
        name="">
        <color
          rgba="0.2 0.2 0.2 1" />
      </material>
    </visual>
    <collision>
      <origin
        xyz="0 0 0"
        rpy="0 0 0" />
      <geometry>
        <mesh
          filename="file://$(find auriga)/description/meshes/base_link.STL" />
      </geometry>
    </collision>
  </link>
  <link
    name="rocker_1_link">
    <inertial>
      <origin
        xyz="-0.00319427397416952 0.0774063348676216 0.0514223730363776"
        rpy="0 0 0" />
      <mass
        value="0.157115010617485" />
      <inertia
        ixx="0.0029864627992537"
        ixy="1.12349826817264E-05"
        ixz="3.1664433625397E-05"
        iyy="0.00259908313149434"
        iyz="-0.000678181482698449"
        izz="0.000411909267858246" />
    </inertial>
    <visual>
      <origin
        xyz="0 0 0"
        rpy="0 0 0" />
      <geometry>
        <mesh
          filename="file://$(find auriga)/description/meshes/rocker_1_link.STL" />
      </geometry>
      <material
        name="">
        <color
          rgba="0.427450980392157 0.447058823529412 0.427450980392157 1" />
      </material>
    </visual>
    <collision>
      <origin
        xyz="0 0 0"
        rpy="0 0 0" />
      <geometry>
        <mesh
          filename="file://$(find auriga)/description/meshes/rocker_1_link.STL" />
      </geometry>
    </collision>
  </link>
  <joint
    name="rocker_1_joint"
    type="fixed">
    <origin
      xyz="0.03499 -0.092655 -0.033"
      rpy="3.1416 0 3.1416" />
    <parent
      link="base_link" />
    <child
      link="rocker_1_link" />
    <axis
      xyz="0 0 0" />
  </joint>
  <link
    name="bogie_1_link">
    <inertial>
      <origin
        xyz="0.0023959 -0.061899 -0.00023965"
        rpy="0 0 0" />
      <mass
        value="0.109" />
      <inertia
        ixx="0.00075509"
        ixy="4.3842E-06"
        ixz="1.6974E-08"
        iyy="0.00066525"
        iyz="2.1776E-06"
        izz="0.00010281" />
    </inertial>
    <visual>
      <origin
        xyz="0 0 0"
        rpy="0 0 0" />
      <geometry>
        <mesh
          filename="file://$(find auriga)/description/meshes/bogie_1_link.STL" />
      </geometry>
      <material
        name="">
        <color
          rgba="0.42745 0.44706 0.42745 1" />
      </material>
    </visual>
    <collision>
      <origin
        xyz="0 0 0"
        rpy="0 0 0" />
      <geometry>
        <mesh
          filename="file://$(find auriga)/description/meshes/bogie_1_link.STL" />
      </geometry>
    </collision>
  </link>
  <joint
    name="bogie_1_joint"
    type="revolute">
    <origin
      xyz="-0.02051 0.053967 -0.099947"
      rpy="0 0 3.1416" />
    <parent
      link="rocker_1_link" />
    <child
      link="bogie_1_link" />
    <axis
      xyz="-1 0 0" />
    <limit
      lower="-0.785"
      upper="0.785"
      effort="10"
      velocity="5" />
  </joint>
  <link
    name="wheel_5_link">
    <inertial>
      <origin
        xyz="0.00416147173779097 -9.28831021262955E-08 1.94176211321812E-07"
        rpy="0 0 0" />
      <mass
        value="0.926156136524473" />
      <inertia
        ixx="0.00219829054546711"
        ixy="-1.07358910102717E-08"
        ixz="8.07356099787813E-09"
        iyy="0.00140016164031924"
        iyz="3.89529542945175E-08"
        izz="0.00140018200801187" />
    </inertial>
    <visual>
      <origin
        xyz="0 0 0"
        rpy="0 0 0" />
      <geometry>
        <mesh
          filename="file://$(find auriga)/description/meshes/wheel_5_link.STL" />
      </geometry>
      <material
        name="">
        <color
          rgba="0.752941176470588 0.752941176470588 0.752941176470588 1" />
      </material>
    </visual>
    <collision>
      <origin
        xyz="0 0 0"
        rpy="0 0 0" />
      <geometry>
        <mesh
          filename="file://$(find auriga)/description/meshes/wheel_5_link.STL" />
      </geometry>
    </collision>
  </link>
  <joint
    name="wheel_5_joint"
    type="continuous">
    <origin
      xyz="0.10265 -0.079036 0.089695"
      rpy="0 0 3.1416" />
    <parent
      link="bogie_1_link" />
    <child
      link="wheel_5_link" />
    <axis
      xyz="-1 0 0" />
  </joint>
  <link
    name="wheel_6_link">
    <inertial>
      <origin
        xyz="0.0041615 -0.00034885 -0.39025"
        rpy="0 0 0" />
      <mass
        value="0.92616" />
      <inertia
        ixx="0.0021983"
        ixy="9.9644E-09"
        ixz="-9.0085E-09"
        iyy="0.0014002"
        iyz="4.0148E-08"
        izz="0.0014002" />
    </inertial>
    <visual>
      <origin
        xyz="0 0 0"
        rpy="0 0 0" />
      <geometry>
        <mesh
          filename="file://$(find auriga)/description/meshes/wheel_6_link.STL" />
      </geometry>
      <material
        name="">
        <color
          rgba="0.75294 0.75294 0.75294 1" />
      </material>
    </visual>
    <collision>
      <origin
        xyz="0 0 0"
        rpy="0 0 0" />
      <geometry>
        <mesh
          filename="file://$(find auriga)/description/meshes/wheel_6_link.STL" />
      </geometry>
    </collision>
  </link>
  <joint
    name="wheel_6_joint"
    type="continuous">
    <origin
      xyz="0.10265 -0.078688 0.29995"
      rpy="0 0 3.1416" />
    <parent
      link="bogie_1_link" />
    <child
      link="wheel_6_link" />
    <axis
      xyz="-1 0 0" />
  </joint>
  <link
    name="wheel_4_link">
    <inertial>
      <origin
        xyz="0.00416147173779091 0.000348722601230034 0.39025104440836"
        rpy="0 0 0" />
      <mass
        value="0.926156136524472" />
      <inertia
        ixx="0.00219829054546711"
        ixy="-1.32650632923669E-08"
        ixz="-2.11656297334914E-09"
        iyy="0.00140013325413858"
        iyz="-1.15497356200624E-08"
        izz="0.00140021039419254" />
    </inertial>
    <visual>
      <origin
        xyz="0 0 0"
        rpy="0 0 0" />
      <geometry>
        <mesh
          filename="file://$(find auriga)/description/meshes/wheel_4_link.STL" />
      </geometry>
      <material
        name="">
        <color
          rgba="0.752941176470588 0.752941176470588 0.752941176470588 1" />
      </material>
    </visual>
    <collision>
      <origin
        xyz="0 0 0"
        rpy="0 0 0" />
      <geometry>
        <mesh
          filename="file://$(find auriga)/description/meshes/wheel_4_link.STL" />
      </geometry>
    </collision>
  </link>
  <joint
    name="wheel_4_joint"
    type="continuous">
    <origin
      xyz="-0.12316 0.13231 -0.19025"
      rpy="0 0 0" />
    <parent
      link="rocker_1_link" />
    <child
      link="wheel_4_link" />
    <axis
      xyz="-1 0 0" />
  </joint>
  <link
    name="rocker_2_link">
    <inertial>
      <origin
        xyz="-0.30934 -0.015249 -0.084422"
        rpy="0 0 0" />
      <mass
        value="0.15712" />
      <inertia
        ixx="0.0029865"
        ixy="1.1235E-05"
        ixz="-3.1664E-05"
        iyy="0.0025991"
        iyz="0.00067818"
        izz="0.00041191" />
    </inertial>
    <visual>
      <origin
        xyz="0 0 0"
        rpy="0 0 0" />
      <geometry>
        <mesh
          filename="file://$(find auriga)/description/meshes/rocker_2_link.STL" />
      </geometry>
      <material
        name="">
        <color
          rgba="0.42745 0.44706 0.42745 1" />
      </material>
    </visual>
    <collision>
      <origin
        xyz="0 0 0"
        rpy="0 0 0" />
      <geometry>
        <mesh
          filename="file://$(find auriga)/description/meshes/rocker_2_link.STL" />
      </geometry>
    </collision>
  </link>
  <joint
    name="rocker_2_joint"
    type="fixed">
    <origin
      xyz="0 0 0"
      rpy="0 0 0" />
    <parent
      link="base_link" />
    <child
      link="rocker_2_link" />
    <axis
      xyz="0 0 0" />
  </joint>
  <link
    name="bogie_2_link">
    <inertial>
      <origin
        xyz="0.00239591308301151 0.0617953988436242 0.00358741675136703"
        rpy="0 0 0" />
      <mass
        value="0.108995977851336" />
      <inertia
        ixx="0.0007550940265459"
        ixy="-4.37688335423889E-06"
        ixz="-2.54091808736551E-07"
        iyy="0.000663370668469634"
        iyz="3.25430149906427E-05"
        izz="0.000104686998401709" />
    </inertial>
    <visual>
      <origin
        xyz="0 0 0"
        rpy="0 0 0" />
      <geometry>
        <mesh
          filename="file://$(find auriga)/description/meshes/bogie_2_link.STL" />
      </geometry>
      <material
        name="">
        <color
          rgba="0.427450980392157 0.447058823529412 0.427450980392157 1" />
      </material>
    </visual>
    <collision>
      <origin
        xyz="0 0 0"
        rpy="0 0 0" />
      <geometry>
        <mesh
          filename="file://$(find auriga)/description/meshes/bogie_2_link.STL" />
      </geometry>
    </collision>
  </link>
  <joint
    name="bogie_2_joint"
    type="revolute">
    <origin
      xyz="-0.32665 -0.038665 0.067793"
      rpy="3.1416 0 3.1416" />
    <parent
      link="rocker_2_link" />
    <child
      link="bogie_2_link" />
    <axis
      xyz="-1 0 0" />
    <limit
      lower="-0.785"
      upper="0.785"
      effort="10"
      velocity="5" />
  </joint>
  <link
    name="wheel_2_link">
    <inertial>
      <origin
        xyz="-2.1518E-07 -5.3832E-09 -0.0041615"
        rpy="0 0 0" />
      <mass
        value="0.92616" />
      <inertia
        ixx="0.0014001"
        ixy="3.1138E-08"
        ixz="1.2067E-08"
        iyy="0.0014002"
        iyz="-5.9011E-09"
        izz="0.0021983" />
    </inertial>
    <visual>
      <origin
        xyz="0 0 0"
        rpy="0 0 0" />
      <geometry>
        <mesh
          filename="file://$(find auriga)/description/meshes/wheel_2_link.STL" />
      </geometry>
      <material
        name="">
        <color
          rgba="0.75294 0.75294 0.75294 1" />
      </material>
    </visual>
    <collision>
      <origin
        xyz="0 0 0"
        rpy="0 0 0" />
      <geometry>
        <mesh
          filename="file://$(find auriga)/description/meshes/wheel_2_link.STL" />
      </geometry>
    </collision>
  </link>
  <joint
    name="wheel_2_joint"
    type="continuous">
    <origin
      xyz="0.10265 0.07334 0.094409"
      rpy="0 1.5708 0" />
    <parent
      link="bogie_2_link" />
    <child
      link="wheel_2_link" />
    <axis
      xyz="0 0 1" />
  </joint>
  <link
    name="wheel_1_link">
    <inertial>
      <origin
        xyz="-0.0041615 -2.0875E-07 5.2503E-08"
        rpy="0 0 0" />
      <mass
        value="0.92616" />
      <inertia
        ixx="0.0021983"
        ixy="1.0043E-08"
        ixz="-8.9202E-09"
        iyy="0.0014002"
        iyz="3.9846E-08"
        izz="0.0014002" />
    </inertial>
    <visual>
      <origin
        xyz="0 0 0"
        rpy="0 0 0" />
      <geometry>
        <mesh
          filename="file://$(find auriga)/description/meshes/wheel_1_link.STL" />
      </geometry>
      <material
        name="">
        <color
          rgba="0.75294 0.75294 0.75294 1" />
      </material>
    </visual>
    <collision>
      <origin
        xyz="0 0 0"
        rpy="0 0 0" />
      <geometry>
        <mesh
          filename="file://$(find auriga)/description/meshes/wheel_1_link.STL" />
      </geometry>
    </collision>
  </link>
  <joint
    name="wheel_1_joint"
    type="continuous">
    <origin
      xyz="0.10265 0.0837717629834123 -0.0852883163107575"
      rpy="0 0 0" />
    <parent
      link="bogie_2_link" />
    <child
      link="wheel_1_link" />
    <axis
      xyz="1 0 0" />
  </joint>
  <link
    name="wheel_3_link">
    <inertial>
      <origin
        xyz="-0.00416147173779097 -6.99332501352679E-08 2.03570656609475E-07"
        rpy="0 0 0" />
      <mass
        value="0.926156136524472" />
      <inertia
        ixx="0.0021982905454671"
        ixy="-1.99317804403964E-09"
        ixz="-1.32841629112928E-08"
        iyy="0.00140021060221958"
        iyz="-1.08307848249764E-08"
        izz="0.00140013304611153" />
    </inertial>
    <visual>
      <origin
        xyz="0 0 0"
        rpy="0 0 0" />
      <geometry>
        <mesh
          filename="file://$(find auriga)/description/meshes/wheel_3_link.STL" />
      </geometry>
      <material
        name="">
        <color
          rgba="0.752941176470588 0.752941176470588 0.752941176470588 1" />
      </material>
    </visual>
    <collision>
      <origin
        xyz="0 0 0"
        rpy="0 0 0" />
      <geometry>
        <mesh
          filename="file://$(find auriga)/description/meshes/wheel_3_link.STL" />
      </geometry>
    </collision>
  </link>
  <joint
    name="wheel_3_joint"
    type="continuous">
    <origin
      xyz="-0.4293 0.04 -0.233"
      rpy="3.1416 0 3.1416" />
    <parent
      link="rocker_2_link" />
    <child
      link="wheel_3_link" />
    <axis
      xyz="1 0 0" />
  </joint>
  <link
    name="lidar_link">
    <inertial>
      <origin
        xyz="0.0225246315179786 0.0252244678162723 0.00689883757739537"
        rpy="0 0 0" />
      <mass
        value="0.0941041855286772" />
      <inertia
        ixx="4.43514677561826E-05"
        ixy="2.9036632805171E-08"
        ixz="-1.51745387499321E-07"
        iyy="6.94753945949236E-05"
        iyz="3.35003193615963E-07"
        izz="2.79104313007998E-05" />
    </inertial>
    <visual>
      <origin
        xyz="0 0 0"
        rpy="0 0 0" />
      <geometry>
        <mesh
          filename="file://$(find auriga)/description/meshes/lidar_link.STL" />
      </geometry>
      <material
        name="">
        <color
          rgba="0.752941176470588 0.752941176470588 0.752941176470588 1" />
      </material>
    </visual>
    <collision>
      <origin
        xyz="0 0 0"
        rpy="0 0 0" />
      <geometry>
        <mesh
          filename="file://$(find auriga)/description/meshes/lidar_link.STL" />
      </geometry>
    </collision>
  </link>
  <joint
    name="lidar_joint"
    type="fixed">
    <origin
      xyz="-0.11141 -0.23235 0.072107"
      rpy="3.1416 0 3.1416" />
    <parent
      link="base_link" />
    <child
      link="lidar_link" />
    <axis
      xyz="0 0 0" />
  </joint>
  <link
    name="camera_link">
    <inertial>
      <origin
        xyz="0 0 0"
        rpy="0 0 0" />
      <mass
        value="0" />
      <inertia
        ixx="0"
        ixy="0"
        ixz="0"
        iyy="0"
        iyz="0"
        izz="0" />
    </inertial>
    <visual>
      <origin
        xyz="0 0 0"
        rpy="0 0 0" />
      <geometry>
        <mesh
          filename="file://$(find auriga)/description/meshes/camera_link.STL" />
      </geometry>
      <material
        name="">
        <color
          rgba="1 1 1 1" />
      </material>
    </visual>
    <collision>
      <origin
        xyz="0 0 0"
        rpy="0 0 0" />
      <geometry>
        <mesh
          filename="file://$(find auriga)/description/meshes/camera_link.STL" />
      </geometry>
    </collision>
  </link>
  <joint
    name="camera_joint"
    type="fixed">
    <origin
      xyz="-0.113225697052003 -0.0537931754289137 0.146634965177554"
      rpy="3.14159265358979 0 3.14159265358979" />
    <parent
      link="base_link" />
    <child
      link="camera_link" />
    <axis
      xyz="0 0 0" />
  </joint>


</robot>